<mujoco model="FA_Drone">
  <compiler angle="radian" meshdir="meshes_FA/" balanceinertia="true" />
  <option impratio="1" gravity="0 0 -9.81" integrator="implicit" density="1.225" viscosity="1.789e-5"> 
  </option>

  <visual>
    <global offwidth="3000" offheight="3000"/>
  </visual>

  <asset>
    <texture builtin="gradient" type="skybox" height="100" width="100" rgb1="1 1 1" rgb2=".6 .8 1"/>
    <texture name="texgeom" builtin="flat" height="1278" mark="cross" markrgb="1 1 1" random="0.01" rgb1="0.8 0.6 0.4" rgb2="0.8 0.6 0.4" type="cube" width="127"/>
    <texture name="texplane" builtin="checker" height="100" width="100" rgb1="0 0 0" rgb2="0.8 0.8 0.8" type="2d"/>
    <material name="MatPlane" reflectance="0.5" shininess="1" specular="1" texrepeat="60 60" texture="texplane"/>
    <mesh name="Base" file="Base.STL"/>
    <mesh name="Arm1_1" file="Arm1_1.STL"/>
    <mesh name="Arm2_1" file="Arm2_1.STL"/>
    <mesh name="Arm1_2" file="Arm1_2.STL"/>
    <mesh name="Arm2_2" file="Arm2_2.STL"/>
  </asset>

  <default>
    <geom contype="0" conaffinity="0" condim="1" solref="0.001 1"/>
    <equality solref="1e-10 1"/>
    <default class="visual">
      <geom group="2" type="mesh" contype="0" conaffinity="0" rgba="1 1 1 1" density="0" />
    </default>
    <default class="collision">
      <geom contype="1" group="3" type="mesh"/>
    </default>
  </default>

  <worldbody>
    <light cutoff="100" diffuse="1 1 1" dir="-0 0 -1.3" directional="true" exponent="1" pos="0 0 1.3" specular=".1 .1 .1"/>
    <geom contype="1" conaffinity="1" condim="3" material="MatPlane" name="floor" pos="0 0 0" rgba="0.4 0.3 0.3 1" size="5 5 0.2" type="plane"/>
    <body name='Base' pos='0 0 0.5' quat="1 0 0 0">
      <freejoint/>
<!--      <joint type="ball" />-->
<!--      <joint axis="0 1 0" pos ="0 0 0" type="hinge"/>-->
      <geom class="collision" mesh="Base"/>
      <geom class="visual" mesh="Base"/>
<!--      <inertial pos="0 0 0" quat="1 0 0 0" mass="0.72" diaginertia="7.4676e-02	7.408e-03 7.9612e-02"/>-->
      <inertial pos="0 0 0" quat="1 0 0 0" mass="0.372" diaginertia="7.4676e-04 7.408e-05 7.9612e-04"/>
      <body name="Arm1_1" pos="0 -0.085 0">
        <inertial pos="0.0057114 -0.076571 0" quat="0.0230564 0.706731 -0.0230564 0.706731" mass="0.1671" diaginertia="0.0021725 0.0017032 0.000478969"/>
        <joint name="J1_1" type='hinge' pos="0 0 0" axis="0 -1 0" damping="0.1"/>
        <geom class="collision" mesh="Arm1_1"/>
        <geom class="visual" mesh="Arm1_1"/>
        <body name="Arm2_1" pos="0 -0.16 0">
          <inertial pos="7.421e-07 1.5047e-07 -0.0032985" quat="1.35189e-06 0.707107 -1.35189e-06 0.707107" mass="0.097595" diaginertia="0.00058352 0.0005727 2.3471e-05"/>
          <joint name="J2_1" type='hinge' pos="0 0 0" axis="1 0 0" damping="0.1"/>
          <geom class="collision" mesh="Arm2_1"/>
          <geom class="visual" mesh="Arm2_1"/>
          <site name="motor1" type="cylinder" pos="0 0 0" size=".02 .01" quat="1 0 0 0" rgba=".3 .8 .3 1"/> Right
        </body>
      </body>

      <body name="Arm1_2" pos="0 0.085 0">
        <inertial pos="-0.0057114 0.076571 0" quat="0.0230564 0.706731 -0.0230564 0.706731" mass="0.1671" diaginertia="0.0021725 0.0017032 0.000478969"/>
        <joint name="J1_2" type='hinge' pos="0 0 0" axis="0 1 0" damping="0.1"/>
        <geom class="collision" mesh="Arm1_2"/>
        <geom class="visual" mesh="Arm1_2"/>
        <body name="Arm2_2" pos="0 0.16 0">
          <inertial pos="1.7925e-06 4.7152e-08 -0.0032972" quat="-2.24978e-06 0.707107 2.24978e-06 0.707107" mass="0.097601" diaginertia="0.00058353 0.0005727 2.3475e-05"/>
          <joint name="J2_2" type='hinge' pos="0 0 0" axis="-1 0 0" damping="0.1"/>
          <geom class="collision" mesh="Arm2_2"/>
          <geom class="visual" mesh="Arm2_2"/>
          <site name="motor2" type="cylinder" pos="0 0 0" size=".02 .01" quat="1 0 0 0" rgba=".3 .8 .3 1"/> Left
        </body>
      </body>

      <site name="body_frame" pos="0 0 0" quat="1 0 0 0"/>
      <site name="x_axis_b" type="box" pos=".1 .0 .0" size=".15 .005 .005" quat="1 0 0 0" rgba="1 0 0 0.2"/>
      <site name="y_axis_b" type="box" pos=".0 .1 .0" size=".15 .005 .005" quat=".707 0 0 .707" rgba="0 1 0 0.2"/>
      <site name="z_axis_b" type="box" pos=".0 .0 .1" size=".15 .005 .005" quat="-.707 0 .707 0" rgba="0 0 1 0.2"/>
    </body>
    <site name="x_axis" type="box" pos=".1 .0 .0" size=".15 .005 .005" quat="1 0 0 0" rgba="1 0 0 0.2"/>
    <site name="y_axis" type="box" pos=".0 .1 .0" size=".15 .005 .005" quat=".707 0 0 .707" rgba="0 1 0 0.2"/>
    <site name="z_axis" type="box" pos=".0 .0 .1" size=".15 .005 .005" quat="-.707 0 .707 0" rgba="0 0 1 0.2"/>
  </worldbody>

  <sensor>
    <framepos name="Body_pos" objtype="site" objname="body_frame"/>       <!-- datasensor[0:3] -->
    <framequat name="Body_quat" objtype="site" objname="body_frame"/>     <!-- datasensor[3:7] -->
    <framelinvel name="Body_linvel" objtype="site" objname="body_frame"/> <!-- datasensor[7:10] -->
    <gyro name="Body_angvel_local" site="body_frame"/>                    <!-- datasensor[10:13] -->
<!--    <frameangvel name="Body_angvel" objtype="site" objname="body_frame"/>-->
<!--    <velocimeter name="Body_linvel_local" site="body_frame"/>-->
  </sensor>

  <actuator>
    <motor name="Motor1" ctrllimited="true" ctrlrange="0 1" gear="0  0. 9 0. 0. -0.144" site="motor1"/> unit: N
    <motor name="Motor2" ctrllimited="true" ctrlrange="0 1" gear="0  0. 9 0. 0. 0.144" site="motor2"/>
    <position name="Servo1_1" joint="J1_1" kp="2" ctrllimited="true" ctrlrange="-5 5"/>
    <position name="Servo2_1" joint="J2_1" kp="2" ctrllimited="true" ctrlrange="-5 5"/>
    <position name="Servo1_2" joint="J1_2" kp="2" ctrllimited="true" ctrlrange="-5 5"/>
    <position name="Servo2_2" joint="J2_2" kp="2" ctrllimited="true" ctrlrange="-5 5"/>
    <velocity name="Servo1_1_" joint="J1_1" kv="0.1"/>
    <velocity name="Servo2_1_" joint="J2_1" kv="0.1"/>
    <velocity name="Servo1_2_" joint="J1_2" kv="0.1"/>
    <velocity name="Servo2_2_" joint="J2_2" kv="0.1"/>
  </actuator>

</mujoco>
